Exception in thread Thread-2:
Traceback (most recent call last):
  File "C:\Program Files\WindowsApps\PythonSoftwareFoundation.Python.3.9_3.9.2032.0_x64__qbz5n2kfra8p0\lib\threading.py", line 973, in _bootstrap_inner
    self.run()
  File "C:\Program Files\WindowsApps\PythonSoftwareFoundation.Python.3.9_3.9.2032.0_x64__qbz5n2kfra8p0\lib\threading.py", line 910, in run
    self._target(*self._args, **self._kwargs)
  File "C:\Users\ab\Documents\GitHub\elsiros_webots\controllers\VIA_PB\communication_manager.py", line 79, in run
    message = self.client.receive()
  File "C:\Users\ab\Documents\GitHub\elsiros_webots\controllers\VIA_PB\robot_client.py", line 99, in receive
    content_size = self.socket.recv(self.message_manager.get_size())
ConnectionResetError: [WinError 10054] \u0423\u0434\u0430\u043b\u0435\u043d\u043d\u044b\u0439 \u0445\u043e\u0441\u0442 \u043f\u0440\u0438\u043d\u0443\u0434\u0438\u0442\u0435\u043b\u044c\u043d\u043e \u0440\u0430\u0437\u043e\u0440\u0432\u0430\u043b \u0441\u0443\u0449\u0435\u0441\u0442\u0432\u0443\u044e\u0449\u0435\u0435 \u043f\u043e\u0434\u043a\u043b\u044e\u0447\u0435\u043d\u0438\u0435
