2021-09-05 22:58:38.867118
2021-09-05 22:59:02.669044
2021-09-05 23:01:23.520881
Exception in thread Thread-2:
Traceback (most recent call last):
  File "C:\Program Files\WindowsApps\PythonSoftwareFoundation.Python.3.9_3.9.2032.0_x64__qbz5n2kfra8p0\lib\threading.py", line 973, in _bootstrap_inner
    self.run()
  File "C:\Program Files\WindowsApps\PythonSoftwareFoundation.Python.3.9_3.9.2032.0_x64__qbz5n2kfra8p0\lib\threading.py", line 910, in run
    self._target(*self._args, **self._kwargs)
  File "C:\Users\ab\Documents\GitHub\elsiros_webots\controllers\VIA_PB\communication_manager.py", line 79, in run
    message = self.client.receive()
  File "C:\Users\ab\Documents\GitHub\elsiros_webots\controllers\VIA_PB\robot_client.py", line 99, in receive
    content_size = self.socket.recv(self.message_manager.get_size())
ConnectionResetError: [WinError 10054] Удаленный хост принудительно разорвал существующее подключение
2021-09-06 00:28:00.235183
2021-09-06 00:29:13.223969
2021-09-06 00:53:03.678917
2021-09-06 00:53:28.000246
