2021-09-08 22:38:50.059777
Exception in thread Thread-2:
Traceback (most recent call last):
  File "C:\Program Files\WindowsApps\PythonSoftwareFoundation.Python.3.9_3.9.2032.0_x64__qbz5n2kfra8p0\lib\threading.py", line 973, in _bootstrap_inner
    self.run()
  File "C:\Program Files\WindowsApps\PythonSoftwareFoundation.Python.3.9_3.9.2032.0_x64__qbz5n2kfra8p0\lib\threading.py", line 910, in run
    self._target(*self._args, **self._kwargs)
  File "C:\Users\ab\Documents\GitHub\elsiros_webots\controllers\player\communication_manager.py", line 79, in run
    message = self.client.receive()
  File "C:\Users\ab\Documents\GitHub\elsiros_webots\controllers\player\robot_client.py", line 99, in receive
    content_size = self.socket.recv(self.message_manager.get_size())
ConnectionResetError: [WinError 10054] Удаленный хост принудительно разорвал существующее подключение
2021-09-08 22:41:46,292 Socket timeout
2021-09-08 22:41:46,804 Socket timeout
2021-09-08 22:41:47,320 Socket timeout
2021-09-08 22:41:47,832 Socket timeout
2021-09-08 22:41:48,346 Socket timeout
2021-09-08 22:41:48,858 Socket timeout
2021-09-08 22:41:49,371 Socket timeout
2021-09-08 22:47:54.603106
Exception in thread Thread-2:
Traceback (most recent call last):
  File "C:\Program Files\WindowsApps\PythonSoftwareFoundation.Python.3.9_3.9.2032.0_x64__qbz5n2kfra8p0\lib\threading.py", line 973, in _bootstrap_inner
    self.run()
  File "C:\Program Files\WindowsApps\PythonSoftwareFoundation.Python.3.9_3.9.2032.0_x64__qbz5n2kfra8p0\lib\threading.py", line 910, in run
    self._target(*self._args, **self._kwargs)
  File "C:\Users\ab\Documents\GitHub\elsiros_webots\controllers\player\communication_manager.py", line 79, in run
    message = self.client.receive()
  File "C:\Users\ab\Documents\GitHub\elsiros_webots\controllers\player\robot_client.py", line 99, in receive
    content_size = self.socket.recv(self.message_manager.get_size())
ConnectionResetError: [WinError 10054] Удаленный хост принудительно разорвал существующее подключение
2021-09-08 23:15:03.154881
ERROR:root:sensor is not enable
ERROR:root:sensor is not enable
ERROR:root:sensor is not enable
ERROR:root:sensor is not enable
ERROR:root:sensor is not enable
ERROR:root:sensor is not enable
ERROR:root:sensor is not enable
ERROR:root:sensor is not enable
ERROR:root:sensor is not enable
ERROR:root:sensor is not enable
ERROR:root:sensor is not enable
ERROR:root:sensor is not enable
ERROR:root:sensor is not enable
ERROR:root:sensor is not enable
ERROR:root:sensor is not enable
ERROR:root:sensor is not enable
ERROR:root:sensor is not enable
ERROR:root:sensor is not enable
ERROR:root:sensor is not enable
ERROR:root:sensor is not enable
ERROR:root:sensor is not enable
ERROR:root:sensor is not enable
ERROR:root:sensor is not enable
ERROR:root:sensor is not enable
ERROR:root:sensor is not enable
ERROR:root:sensor is not enable
ERROR:root:sensor is not enable
ERROR:root:sensor is not enable
ERROR:root:sensor is not enable
ERROR:root:sensor is not enable
ERROR:root:sensor is not enable
ERROR:root:sensor is not enable
ERROR:root:sensor is not enable
ERROR:root:sensor is not enable
ERROR:root:sensor is not enable
ERROR:root:sensor is not enable
ERROR:root:sensor is not enable
ERROR:root:sensor is not enable
ERROR:root:sensor is not enable
ERROR:root:sensor is not enable
ERROR:root:sensor is not enable
ERROR:root:sensor is not enable
ERROR:root:sensor is not enable
Exception in thread Thread-2:
Traceback (most recent call last):
  File "C:\Program Files\WindowsApps\PythonSoftwareFoundation.Python.3.9_3.9.2032.0_x64__qbz5n2kfra8p0\lib\threading.py", line 973, in _bootstrap_inner
    self.run()
  File "C:\Program Files\WindowsApps\PythonSoftwareFoundation.Python.3.9_3.9.2032.0_x64__qbz5n2kfra8p0\lib\threading.py", line 910, in run
    self._target(*self._args, **self._kwargs)
  File "C:\Users\ab\Documents\GitHub\elsiros_webots\controllers\player\communication_manager.py", line 79, in run
    message = self.client.receive()
  File "C:\Users\ab\Documents\GitHub\elsiros_webots\controllers\player\robot_client.py", line 99, in receive
    content_size = self.socket.recv(self.message_manager.get_size())
ConnectionResetError: [WinError 10054] Удаленный хост принудительно разорвал существующее подключение
2021-09-08 23:17:41.942497
Exception in thread Thread-2:
Traceback (most recent call last):
  File "C:\Program Files\WindowsApps\PythonSoftwareFoundation.Python.3.9_3.9.2032.0_x64__qbz5n2kfra8p0\lib\threading.py", line 973, in _bootstrap_inner
    self.run()
  File "C:\Program Files\WindowsApps\PythonSoftwareFoundation.Python.3.9_3.9.2032.0_x64__qbz5n2kfra8p0\lib\threading.py", line 910, in run
    self._target(*self._args, **self._kwargs)
  File "C:\Users\ab\Documents\GitHub\elsiros_webots\controllers\player\communication_manager.py", line 79, in run
    message = self.client.receive()
  File "C:\Users\ab\Documents\GitHub\elsiros_webots\controllers\player\robot_client.py", line 99, in receive
    content_size = self.socket.recv(self.message_manager.get_size())
ConnectionResetError: [WinError 10054] Удаленный хост принудительно разорвал существующее подключение
